Workbook

Sheet 1. Raw Data
A1: IMPL | B1: Load | C1: Time of tests (min) | D1: Total Requests | E1: Success Requests | F1: Failed Requests | G1: Error Rate (%) | H1: Req/Sec | I1: Min (ms) | J1: Mean (ms) | K1: Max (ms) | L1: Stdard Deviation (ms) | M1: P50 (ms) | N1: P75 (ms) | O1: P95 (ms) | P1: P99 (ms) | Q1: GC Time (ms) | R1: GC Collections | S1: Heap Peak (GB) | T1: Heap Peak (%) | U1: CPU Peak (%) | V1: < 800ms | W1: 800-1200ms | X1: > 1200ms | Y1: < 800ms (%) | Z1: 800-1200ms (%) | AA1: > 1200ms (%) | AB1: Total Requests Prometheus | AC1: Delta Gatling Prometheus | AD1: Sync Status | AE1: Error Status | AF1: Timestamp
A2: Java | B2: 100 | C2: 5 | D2: 30000 | E2: 30000 | F2: 0 | G2: 0 | H2: 100 | I2: 0 | J2: 2 | K2: 94 | L2: 2 | M2: 2 | N2: 2 | O2: 3 | P2: 4 | Q2: 0 | R2: 0 | S2: 0.91 | T2: 15 | U2: 40.02 | V2: 30000 | W2: 0 | X2: 0 | Y2: 100 | Z2: 0 | AA2: 0 | AB2: 30079 | AC2: =AB2-D2 -> 79 | AD2: GOOD | AE2: EXCELLENT | AF2: 46005.795
K3: 100 | L3: 1 | O3: 2 | Q3: 0 | R3: 0 | S3: 1.58 | T3: 26 | U3: 41.77 | V3: 30000 | W3: 0 | X3: 0 | Y3: 100 | Z3: 0 | AA3: 0 | AB3: 30078 | AC3: =AB3-D3 -> 30078 | AF3: 46005.805
K4: 243 | L4: 4 | O4: 2 | Q4: 34 | R4: 2 | S4: 1 | T4: 16 | U4: 54.3 | V4: 30000 | W4: 0 | X4: 0 | Y4: 100 | Z4: 0 | AA4: 0 | AB4: 30077 | AC4: =AB4-D4 -> 30077 | AF4: 46005.813
K5: 116 | L5: 2 | O5: 2 | Q5: 32 | R5: 2 | S5: 1 | T5: 16 | U5: 43.39 | V5: 30000 | W5: 0 | X5: 0 | Y5: 100 | Z5: 0 | AA5: 0 | AB5: 30077 | AC5: =AB5-D5 -> 30077 | AF5: 46005.821
K6: 96 | L6: 2 | O6: 3 | Q6: 0 | R6: 0 | S6: 0.91 | T6: 15 | U6: 35.23 | V6: 30000 | W6: 0 | X6: 0 | Y6: 100 | Z6: 0 | AA6: 0 | AB6: 30077 | AC6: =D6-AB6 -> -30077 | AF6: 46005.83
K7: 105 | L7: 2 | O7: 3 | Q7: 0 | R7: 0 | S7: 0.98 | T7: 16 | U7: 46.81 | V7: 30000 | W7: 0 | X7: 0 | Y7: 100 | Z7: 0 | AA7: 0 | AB7: 30077 | AC7: =AB7-D7 -> 30077 | AF7: 46005.839
B8: 500 | C8: 5 | D8: 150000 | E8: 150000 | F8: 0 | G8: 0 | H8: 500 | I8: 0 | J8: 138 | K8: 9407 | L8: 594 | M8: 1 | N8: 1 | O8: 1036 | P8: 3100 | Q8: 143 | R8: 5 | S8: 2.35 | T8: 39 | U8: 86.23 | V8: 140937 | W8: 2188 | X8: 6875 | Y8: 94 | Z8: 1 | AA8: 5 | AB8: 150078 | AC8: =AB8-D8 -> 78 | AD8: EXCELLENT | AE8: EXCELLENT | AF8: 46007.269
J9: 54 | K9: 5586 | L9: 329 | O9: 3 | P9: 1725 | Q9: 232 | R9: 5 | S9: 2.35 | T9: 39 | U9: 66.07 | V9: 146256 | W9: 1118 | X9: 2626 | Y9: 98 | Z9: 1 | AA9: 2 | AB9: 150080 | AC9: =AB9-D9 -> 150080 | AF9: 46007.278
J10: 26 | K10: 3803 | L10: 183 | O10: 2 | P10: 909 | Q10: 0 | R10: 0 | S10: 2.34 | T10: 39 | U10: 63.75 | V10: 148250 | W10: 741 | X10: 1009 | Y10: 99 | Z10: 0 | AA10: 1 | AB10: 150078 | AC10: =AB10-D10 -> 150078 | AF10: 46007.29
J11: 488 | K11: 14660 | L11: 1595 | O11: 4696 | P11: 7695 | Q11: 0 | R11: 0 | S11: 2.37 | T11: 39 | U11: 80.15 | V11: 134104 | W11: 622 | X11: 15274 | Y11: 89 | Z11: 0 | AA11: 10 | AB11: 150078 | AC11: =AB11-D11 -> 150078 | AF11: 46007.299
J12: 26 | K12: 4304 | L12: 177 | O12: 2 | P12: 841 | Q12: 0 | R12: 0 | S12: 2.27 | T12: 37 | U12: 67.21 | V12: 148334 | W12: 892 | X12: 774 | Y12: 99 | Z12: 1 | AA12: 1 | AB12: 150079 | AC12: =AB12-D12 -> 150079 | AF12: 46007.308
J13: 36 | K13: 6301 | L13: 248 | O13: 3 | P13: 1191 | Q13: 102 | R13: 5 | S13: 2.27 | T13: 37 | U13: 65.75 | V13: 147524 | W13: 1016 | X13: 1460 | Y13: 98 | Z13: 1 | AA13: 1 | AB13: 150082 | AC13: =AB13-D13 -> 150082 | AF13: 46007.317
B14: 1000 | C14: 5 | D14: 300000 | E14: 300000 | F14: 0 | G14: 0 | H14: 1000 | I14: 0 | J14: 543 | K14: 13377 | L14: 1786 | M14: 1 | N14: 1 | O14: 5106 | P14: 8920 | Q14: 0 | R14: 0 | S14: 2.33 | T14: 38 | U14: 84.28 | V14: 269069 | W14: 1639 | X14: 29292 | Y14: 90 | Z14: 1 | AA14: 10 | AB14: 300079 | AC14: =AB14-D14 -> 79 | AD14: EXCELLENT | AE14: EXCELLENT | AF14: 46008.256
E15: 300000 | F15: 0 | G15: 0 | H15: 1000 | I15: 0 | J15: 587 | K15: 15800 | L15: 1857 | M15: 1 | N15: 1 | O15: 5420 | P15: 9186 | Q15: 549 | R15: 11 | S15: 2.34 | T15: 39 | U15: 77.98 | V15: 265423 | W15: 771 | X15: 33806 | Y15: 88 | Z15: 0 | AA15: 11 | AB15: 300078 | AC15: =AB15-D15 -> 300078 | AD15: EXCELLENT | AE15: EXCELLENT | AF15: 46008.265
E16: 300000 | F16: 0 | G16: 0 | H16: 1000 | I16: 0 | J16: 530 | K16: 14482 | L16: 1677 | M16: 1 | N16: 1 | O16: 4799 | P16: 8148 | Q16: 986 | R16: 12 | S16: 2.31 | T16: 38 | U16: 78.97 | V16: 266612 | W16: 807 | X16: 32581 | Y16: 89 | Z16: 0 | AA16: 11 | AB16: 300078 | AC16: =AB16-D16 -> 300078 | AD16: EXCELLENT | AE16: EXCELLENT | AF16: 46008.274
E17: 300000 | F17: 0 | G17: 0 | H17: 1000 | I17: 0 | J17: 918 | K17: 23005 | L17: 2680 | M17: 1 | N17: 1 | O17: 6068 | P17: 13773 | Q17: 0 | R17: 0 | S17: 2.3 | T17: 38 | U17: 81.11 | V17: 257505 | W17: 576 | X17: 41919 | Y17: 86 | Z17: 0 | AA17: 14 | AB17: 300080 | AC17: =AB17-D17 -> 300080 | AD17: EXCELLENT | AE17: EXCELLENT | AF17: 46008.283
E18: 270880 | F18: 29120 | G18: 9.7 | H18: 837.989 | I18: 1 | J18: 27538 | K18: 212301 | L18: 35842 | M18: 8872 | N18: 46234 | O18: 98447 | P18: 148247 | Q18: 9555 | R18: 50 | S18: 1.2 | T18: 20 | U18: 72.67 | V18: 76691 | W18: 19734 | X18: 174455 | Y18: 26 | Z18: 7 | AA18: 58 | AB18: 272982 | AC18: =AB18-D18 -> 272982 | AD18: GOOD | AE18: HIGH | AF18: 46008.292
E19: 300000 | F19: 0 | G19: 0 | H19: 1000 | I19: 0 | J19: 545 | K19: 16892 | L19: 1827 | M19: 1 | N19: 1 | O19: 3997 | P19: 9767 | Q19: 0 | R19: 0 | S19: 2.37 | T19: 39 | U19: 78.64 | V19: 266503 | W19: 1423 | X19: 32074 | Y19: 89 | Z19: 0 | AA19: 11 | AB19: 300079 | AC19: =AB19-D19 -> 300079 | AD19: EXCELLENT | AE19: EXCELLENT | AF19: 46008.3
A20: Clojure-Idiomatic | B20: 100 | C20: 5 | D20: 30000 | E20: 30000 | F20: 0 | G20: 0 | H20: 100 | I20: 0 | J20: 2 | K20: 108 | L20: 2 | M20: 2 | N20: 2 | O20: 3 | P20: 4 | Q20: 34 | R20: 2 | S20: 1.45 | T20: 24 | U20: 34.58 | V20: 30000 | W20: 0 | X20: 0 | Y20: 100 | Z20: 0 | AA20: 0 | AB20: 30077 | AC20: =AB20-D20 -> 77 | AD20: GOOD | AE20: EXCELLENT | AF20: 46006.259
K21: 242 | L21: 3 | O21: 2 | Q21: 32 | R21: 2 | S21: 1 | T21: 16 | U21: 50.32 | V21: 30000 | W21: 0 | X21: 0 | Y21: 100 | Z21: 0 | AA21: 0 | AB21: 30077 | AC21: =AB21-D21 -> 30077 | AF21: 46006.267
K22: 114 | L22: 2 | O22: 3 | Q22: 0 | R22: 0 | S22: 1.39 | T22: 23 | U22: 41.72 | V22: 30000 | W22: 0 | X22: 0 | Y22: 100 | Z22: 0 | AA22: 0 | AB22: 30077 | AC22: =AB22-D22 -> 30077 | AF22: 46006.275
K23: 110 | L23: 2 | O23: 3 | Q23: 0 | R23: 0 | S23: 1.14 | T23: 19 | U23: 40.04 | V23: 30000 | W23: 0 | X23: 0 | Y23: 100 | Z23: 0 | AA23: 0 | AB23: 30077 | AC23: =AB23-D23 -> 30077 | AF23: 46006.284
K24: 116 | L24: 2 | O24: 3 | Q24: 0 | R24: 0 | S24: 1.27 | T24: 21 | U24: 38.98 | V24: 30000 | W24: 0 | X24: 0 | Y24: 100 | Z24: 0 | AA24: 0 | AB24: 30077 | AC24: =AB24-D24 -> 30077 | AF24: 46006.293
K25: 266 | L25: 4 | O25: 2 | Q25: 45 | R25: 3 | S25: 1.3 | T25: 21 | U25: 41.58 | V25: 30000 | W25: 0 | X25: 0 | Y25: 100 | Z25: 0 | AA25: 0 | AB25: 30077 | AC25: =AB25-D25 -> 30077 | AF25: 46006.302
B26: 500 | C26: 5 | D26: 150000 | E26: 150000 | F26: 0 | G26: 0 | H26: 500 | I26: 0 | J26: 102 | K26: 8121 | L26: 515 | M26: 1 | N26: 1 | O26: 399 | P26: 2912 | Q26: 115 | R26: 6 | S26: 2.32 | T26: 38 | U26: 72.82 | V26: 143616 | W26: 1335 | X26: 5049 | Y26: 96 | Z26: 1 | AA26: 3 | AB26: 150079 | AC26: =AB26-D26 -> 79 | AD26: EXCELLENT | AE26: EXCELLENT | AF26: 46007.499
J27: 9377 | K27: 48615 | L27: 8841 | M27: 8721 | N27: 18359 | O27: 20896 | P27: 25260 | Q27: 834 | R27: 10 | S27: 2.3 | T27: 38 | U27: 85.18 | V27: 59370 | W27: 366 | X27: 90264 | Y27: 40 | Z27: 0 | AA27: 60 | AB27: 150076 | AC27: =AB27-D27 -> 150076 | AF27: 46007.508
J28: 56 | K28: 6466 | L28: 345 | M28: 1 | N28: 1 | O28: 14 | P28: 1815 | Q28: 77 | R28: 6 | S28: 2.29 | T28: 38 | U28: 68.27 | V28: 146296 | W28: 1103 | X28: 2601 | Y28: 98 | Z28: 1 | AA28: 2 | AB28: 150077 | AC28: =AB28-D28 -> 150077 | AF28: 46007.516
J29: 64 | K29: 8486 | L29: 398 | M29: 1 | N29: 1 | O29: 18 | P29: 1889 | Q29: 541 | R29: 8 | S29: 2.37 | T29: 39 | U29: 72.19 | V29: 145830 | W29: 915 | X29: 3255 | Y29: 97 | Z29: 1 | AA29: 2 | AB29: 150078 | AC29: =AB29-D29 -> 150078 | AF29: 46007.525
J30: 68 | K30: 7410 | L30: 405 | M30: 1 | N30: 1 | O30: 10 | P30: 2078 | Q30: 297 | R30: 7 | S30: 2.38 | T30: 39 | U30: 65.03 | V30: 145604 | W30: 1086 | X30: 3310 | Y30: 97 | Z30: 1 | AA30: 2 | AB30: 150079 | AC30: =AB30-D30 -> 150079 | AF30: 46007.533
J31: 106 | K31: 8533 | L31: 556 | M31: 1 | N31: 1 | O31: 314 | P31: 3260 | Q31: 331 | R31: 8 | S31: 2.35 | T31: 39 | U31: 73.02 | V31: 144157 | W31: 1018 | X31: 4825 | Y31: 96 | Z31: 1 | AA31: 3 | AB31: 150077 | AC31: =AB31-D31 -> 150077 | AF31: 46007.542
B32: 1000 | C32: 5 | D32: 300000 | E32: 300000 | F32: 0 | G32: 0 | H32: 1000 | I32: 0 | J32: 562 | K32: 14895 | L32: 1837 | M32: 1 | N32: 1 | O32: 4976 | P32: 9453 | Q32: 0 | R32: 0 | S32: 2.36 | T32: 39 | U32: 76.92 | V32: 266469 | W32: 1272 | X32: 32259 | Y32: 89 | Z32: 0 | AA32: 11 | AB32: 300078 | AC32: =AB32-D32 -> 78 | AD32: EXCELLENT | AE32: EXCELLENT | AF32: 46008.568
J33: 667 | K33: 18628 | L33: 2025 | O33: 4872 | P33: 10202 | Q33: 887 | R33: 14 | S33: 2.35 | T33: 39 | U33: 82.26 | V33: 261089 | W33: 1477 | X33: 37434 | Y33: 87 | Z33: 0 | AA33: 12 | AB33: 300080 | AC33: =AB33-D33 -> 300080 | AF33: 46008.577
J34: 619 | K34: 15706 | L34: 1901 | O34: 5260 | P34: 9555 | Q34: 1339 | R34: 18 | S34: 2.35 | T34: 39 | U34: 75.22 | V34: 262222 | W34: 1197 | X34: 36581 | Y34: 87 | Z34: 0 | AA34: 12 | AB34: 300082 | AC34: =AB34-D34 -> 300082 | AF34: 46008.586
J35: 530 | K35: 14034 | L35: 1767 | O35: 4296 | P35: 9801 | Q35: 936 | R35: 16 | S35: 2.29 | T35: 38 | U35: 79.06 | V35: 266421 | W35: 1587 | X35: 31992 | Y35: 89 | Z35: 1 | AA35: 11 | AB35: 300080 | AC35: =AB35-D35 -> 300080 | AF35: 46008.595
J36: 598 | K36: 17922 | L36: 1905 | O36: 4534 | P36: 10193 | Q36: 0 | R36: 0 | S36: 2.36 | T36: 39 | U36: 79.28 | V36: 264095 | W36: 684 | X36: 35221 | Y36: 88 | Z36: 0 | AA36: 12 | AB36: 300080 | AC36: =AB36-D36 -> 300080 | AF36: 46008.604
J37: 795 | K37: 22882 | L37: 2483 | O37: 5289 | P37: 13317 | Q37: 1566 | R37: 16 | S37: 2.36 | T37: 39 | U37: 84.64 | V37: 258630 | W37: 1337 | X37: 40033 | Y37: 86 | Z37: 0 | AA37: 13 | AB37: 300078 | AC37: =AB37-D37 -> 300078 | AF37: 46008.612
A38: Clojure-Interop | B38: 100 | C38: 5 | D38: 30000 | E38: 30000 | F38: 0 | G38: 0 | H38: 100 | I38: 0 | J38: 2 | K38: 76 | L38: 1 | M38: 2 | N38: 2 | O38: 3 | P38: 4 | Q38: 0 | R38: 0 | S38: 1.56 | T38: 26 | U38: 42.12 | V38: 30000 | W38: 0 | X38: 0 | Y38: 100 | Z38: 0 | AA38: 0 | AB38: 30077 | AC38: =AB38-D38 -> 77 | AD38: GOOD | AE38: EXCELLENT | AF38: 46006.501
K39: 81 | L39: 1 | O39: 3 | P39: 4 | Q39: 0 | R39: 0 | S39: 0.85 | T39: 14 | U39: 46.98 | V39: 30000 | W39: 0 | X39: 0 | Y39: 100 | Z39: 0 | AA39: 0 | AB39: 30078 | AC39: =AB39-D39 -> 30078 | AF39: 46006.509
K40: 93 | L40: 1 | O40: 3 | P40: 4 | Q40: 36 | R40: 2 | S40: 0.96 | T40: 16 | U40: 54.55 | V40: 30000 | W40: 0 | X40: 0 | Y40: 100 | Z40: 0 | AA40: 0 | AB40: 30077 | AC40: =AB40-D40 -> 30077 | AF40: 46006.519
...

Sheet 2. General Statistical Analysis
A1: Load | B1: Metric | C1: Java AVG | D1: Idiomatic AVG | E1: Interop AVG | F1: Best AVG | G1: Java STD DEV | H1: Idiomatic STD DEV | I1: Interop STD DEV | J1: Best STD DEV | K1: Java CV% | L1: Idiomatic CV% | M1: Interop CV% | N1: Best CV%
A2: 100 | B2: P95 (ms) | C2: =AVERAGE('1. Raw Data'!O2:O7) -> 2.5 | D2: =AVERAGE('1. Raw Data'!O20:O25) -> 2.6666667 | E2: =AVERAGE('1. Raw Data'!O38:O43) -> 2.6666667 | F2: Java | G2: =STDEV('1. Raw Data'!O2:O7) -> 0.54772256 | H2: =STDEV('1. Raw Data'!O20:O25) -> 0.51639778 | I2: =STDEV('1. Raw Data'!O38:O43) -> 0.51639778 | J2: DRAW | K2: =((G2/C2)*100) -> 21.908902 | L2: =((H2/D2)*100) -> 19.364917 | M2: =((I2/E2)*100) -> 19.364917 | N2: DRAW
B3: P99 (ms) | C3: =AVERAGE('1. Raw Data'!P2:P7) -> 4 | D3: =AVERAGE('1. Raw Data'!P20:P25) -> 4 | E3: =AVERAGE('1. Raw Data'!P38:P43) -> 4 | F3: DRAW | G3: =STDEV('1. Raw Data'!P2:P7) -> #DIV/0! | H3: =STDEV('1. Raw Data'!P20:P25) -> #DIV/0! | I3: =STDEV('1. Raw Data'!P38:P43) -> 0 | J3: DRAW | K3: =((G3/C3)*100) -> #DIV/0! | L3: =((H3/D3)*100) -> #DIV/0! | M3: =((I3/E3)*100) -> 0 | N3: DRAW
B4: GC Time (ms) | C4: =AVERAGE('1. Raw Data'!Q2:Q7) -> 11 | D4: =AVERAGE('1. Raw Data'!Q20:Q25) -> 18.5 | E4: =AVERAGE('1. Raw Data'!Q38:Q43) -> 17.666667 | F4: Java | G4: =STDEV('1. Raw Data'!Q2:Q7) -> 17.052859 | H4: =STDEV('1. Raw Data'!Q20:Q25) -> 20.743674 | I4: =STDEV('1. Raw Data'!Q38:Q43) -> 19.724773 | J4: Java | K4: =((G4/C4)*100) -> 155.02599 | L4: =((H4/D4)*100) -> 112.12797 | M4: =((I4/E4)*100) -> 111.64966 | N4: Interop
B5: GC Collections | C5: =AVERAGE('1. Raw Data'!R2:R7) -> 0.66666667 | D5: =AVERAGE('1. Raw Data'!R20:R25) -> 1.1666667 | E5: =AVERAGE('1. Raw Data'!R38:R43) -> 1 | F5: Java | G5: =STDEV('1. Raw Data'!R2:R7) -> 1.0327956 | H5: =STDEV('1. Raw Data'!R20:R25) -> 1.3291601 | I5: =STDEV('1. Raw Data'!R38:R43) -> 1.0954451 | J5: Java | K5: =((G5/C5)*100) -> 154.91933 | L5: =((H5/D5)*100) -> 113.92801 | M5: =((I5/E5)*100) -> 109.54451 | N5: Interop
A6: 500 | B6: P95 (ms) | C6: =AVERAGE('1. Raw Data'!O8:O13) -> 957 | D6: =AVERAGE('1. Raw Data'!O26:O31) -> 3608.5 | E6: =AVERAGE('1. Raw Data'!O44:O49) -> 383.83333 | F6: Interop | G6: =STDEV('1. Raw Data'!O8:O13) -> 1877.7989 | H6: =STDEV('1. Raw Data'!O26:O31) -> 8470.8158 | I6: =STDEV('1. Raw Data'!O44:O49) -> 927.95267 | J6: Interop | K6: =((G6/C6)*100) -> 196.21723 | L6: =((H6/D6)*100) -> 234.74618 | M6: =((I6/E6)*100) -> 241.75927 | N6: Java
B7: P99 (ms) | C7: =AVERAGE('1. Raw Data'!P8:P13) -> 2576.8333 | D7: =AVERAGE('1. Raw Data'!P26:P31) -> 6202.3333 | E7: =AVERAGE('1. Raw Data'!P44:P49) -> 2565.6667 | F7: Interop | G7: =STDEV('1. Raw Data'!P8:P13) -> 2642.3578 | H7: =STDEV('1. Raw Data'!P26:P31) -> 9354.5918 | I7: =STDEV('1. Raw Data'!P44:P49) -> 2305.1642 | J7: Interop | K7: =((G7/C7)*100) -> 102.54283 | L7: =((H7/D7)*100) -> 150.82375 | M7: =((I7/E7)*100) -> 89.846596 | N7: Interop
B8: GC Time (ms) | C8: =AVERAGE('1. Raw Data'!Q8:Q13) -> 79.5 | D8: =AVERAGE('1. Raw Data'!Q26:Q31) -> 365.83333 | E8: =AVERAGE('1. Raw Data'!Q44:Q49) -> 171.16667 | F8: Java | G8: =STDEV('1. Raw Data'!Q8:Q13) -> 96.701086 | H8: =STDEV('1. Raw Data'!Q26:Q31) -> 283.60424 | I8: =STDEV('1. Raw Data'!Q44:Q49) -> 187.43683 | J8: Java | K8: =((G8/C8)*100) -> 121.63659 | L8: =((H8/D8)*100) -> 77.5228 | M8: =((I8/E8)*100) -> 109.50545 | N8: Idiomatic
B9: GC Collections | C9: =AVERAGE('1. Raw Data'!R8:R13) -> 2.5 | D9: =AVERAGE('1. Raw Data'!R26:R31) -> 7.5 | E9: =AVERAGE('1. Raw Data'!R44:R49) -> 3.5 | F9: Java | G9: =STDEV('1. Raw Data'!R8:R13) -> 2.7386128 | H9: =STDEV('1. Raw Data'!R26:R31) -> 1.5165751 | I9: =STDEV('1. Raw Data'!R44:R49) -> 2.8106939 | J9: Idiomatic | K9: =((G9/C9)*100) -> 109.54451 | L9: =((H9/D9)*100) -> 20.221001 | M9: =((I9/E9)*100) -> 80.305539 | N9: Idiomatic
A10: 1000 | B10: P95 (ms) | C10: =AVERAGE('1. Raw Data'!O14:O19) -> 20639.5 | D10: =AVERAGE('1. Raw Data'!O32:O37) -> 4871.1667 | E10: =AVERAGE('1. Raw Data'!O50:O55) -> 6978.5 | F10: Idiomatic | G10: =STDEV('1. Raw Data'!O14:O19) -> 38123.884 | H10: =STDEV('1. Raw Data'!O32:O37) -> 395.28846 | I10: =STDEV('1. Raw Data'!O50:O55) -> 3941.4051 | J10: Idiomatic | K10: =((G10/C10)*100) -> 184.71322 | L10: =((H10/D10)*100) -> 8.1148622 | M10: =((I10/E10)*100) -> 56.479259 | N10: Idiomatic
B11: P99 (ms) | C11: =AVERAGE('1. Raw Data'!P14:P19) -> 33006.833 | D11: =AVERAGE('1. Raw Data'!P32:P37) -> 10420.167 | E11: =AVERAGE('1. Raw Data'!P50:P55) -> 11939 | F11: Idiomatic | G11: =STDEV('1. Raw Data'!P14:P19) -> 56490.522 | H11: =STDEV('1. Raw Data'!P32:P37) -> 1453.144 | I11: =STDEV('1. Raw Data'!P50:P55) -> 4654.7695 | J11: Idiomatic | K11: =((G11/C11)*100) -> 171.14796 | L11: =((H11/D11)*100) -> 13.945496 | M11: =((I11/E11)*100) -> 38.987935 | N11: Idiomatic
B12: GC Time (ms) | C12: =AVERAGE('1. Raw Data'!Q14:Q19) -> 1848.3333 | D12: =AVERAGE('1. Raw Data'!Q32:Q37) -> 788 | E12: =AVERAGE('1. Raw Data'!Q50:Q55) -> 1068.3333 | F12: Idiomatic | G12: =STDEV('1. Raw Data'!Q14:Q19) -> 3796.6724 | H12: =STDEV('1. Raw Data'!Q32:Q37) -> 660.67814 | I12: =STDEV('1. Raw Data'!Q50:Q55) -> 777.76183 | J12: Idiomatic | K12: =((G12/C12)*100) -> 205.41059 | L12: =((H12/D12)*100) -> 83.842403 | M12: =((I12/E12)*100) -> 72.801419 | N12: Interop
B13: GC Collections | C13: =AVERAGE('1. Raw Data'!R14:R19) -> 12.166667 | D13: =AVERAGE('1. Raw Data'!R32:R37) -> 10.666667 | E13: =AVERAGE('1. Raw Data'!R50:R55) -> 12.333333 | F13: Idiomatic | G13: =STDEV('1. Raw Data'!R14:R19) -> 19.374382 | H13: =STDEV('1. Raw Data'!R32:R37) -> 8.3586283 | I13: =STDEV('1. Raw Data'!R50:R55) -> 6.918574 | J13: Interop | K13: =((G13/C13)*100) -> 159.24149 | L13: =((H13/D13)*100) -> 78.36214 | M13: =((I13/E13)*100) -> 56.096546 | N13: Interop

Sheet 3. Statistical Analysis Without
A1: Load | B1: Metric | C1: Java AVG | D1: Idiomatic AVG | E1: Interop AVG | F1: Best AVG | G1: Java STD DEV | H1: Idiomatic STD DEV | I1: Interop STD DEV | J1: Best STD DEV | K1: Java CV% | L1: Idiomatic CV% | M1: Interop CV% | N1: Best CV%
A2: 100 | B2: P95 (ms) | C2: =AVERAGE('1. Raw Data'!O2:O7) -> 2.5 | D2: =AVERAGE('1. Raw Data'!O20:O25) -> 2.6666667 | E2: =AVERAGE('1. Raw Data'!O38:O43) -> 2.6666667 | F2: DRAW | G2: =STDEV('1. Raw Data'!O2:O7) -> 0.54772256 | H2: =STDEV('1. Raw Data'!O20:O25) -> 0.51639778 | I2: =STDEV('1. Raw Data'!O38:O43) -> 0.51639778 | J2: Idiomatic | K2: =((G2/C2)*100) -> 21.908902 | L2: =((H2/D2)*100) -> 19.364917 | M2: =((I2/E2)*100) -> 19.364917 | N2: Idiomatic
B3: P99 (ms) | C3: =AVERAGE('1. Raw Data'!P2:P7) -> 4 | D3: =AVERAGE('1. Raw Data'!P20:P25) -> 4 | E3: =AVERAGE('1. Raw Data'!P38:P43) -> 4 | F3: DRAW | G3: =STDEV('1. Raw Data'!P2:P7) -> #DIV/0! | H3: =STDEV('1. Raw Data'!P20:P25) -> #DIV/0! | I3: =STDEV('1. Raw Data'!P38:P43) -> 0 | J3: DRAW | K3: =((G3/C3)*100) -> #DIV/0! | L3: =((H3/D3)*100) -> #DIV/0! | M3: =((I3/E3)*100) -> 0 | N3: DRAW
B4: GC Time (ms) | C4: =AVERAGE('1. Raw Data'!Q2:Q7) -> 11 | D4: =AVERAGE('1. Raw Data'!Q20:Q25) -> 18.5 | E4: =AVERAGE('1. Raw Data'!Q38:Q43) -> 17.666667 | F4: Java | G4: =STDEV('1. Raw Data'!Q2:Q7) -> 17.052859 | H4: =STDEV('1. Raw Data'!Q20:Q25) -> 20.743674 | I4: =STDEV('1. Raw Data'!Q38:Q43) -> 19.724773 | J4: Java | K4: =((G4/C4)*100) -> 155.02599 | L4: =((H4/D4)*100) -> 112.12797 | M4: =((I4/E4)*100) -> 111.64966 | N4: Interop
B5: GC Collections | C5: =AVERAGE('1. Raw Data'!R2:R7) -> 0.66666667 | D5: =AVERAGE('1. Raw Data'!R20:R25) -> 1.1666667 | E5: =AVERAGE('1. Raw Data'!R38:R43) -> 1 | F5: Java | G5: =STDEV('1. Raw Data'!R2:R7) -> 1.0327956 | H5: =STDEV('1. Raw Data'!R20:R25) -> 1.3291601 | I5: =STDEV('1. Raw Data'!R38:R43) -> 1.0954451 | J5: Java | K5: =((G5/C5)*100) -> 154.91933 | L5: =((H5/D5)*100) -> 113.92801 | M5: =((I5/E5)*100) -> 109.54451 | N5: Interop
A6: 500 | B6: P95 (ms) | C6: =AVERAGE('1. Raw Data'!O7:O12) -> 957 | D6: =AVERAGE('1. Raw Data'!O26,'1. Raw Data'!O28:O31) -> 151 | E6: =AVERAGE('1. Raw Data'!O44:O48) -> 5 | F6: Interop | G6: =STDEV('1. Raw Data'!O8:O13) -> 1877.7989 | H6: =STDEV('1. Raw Data'!O26,'1. Raw Data'!O28:O31) -> 190.00789 | I6: =STDEV('1. Raw Data'!O44:O48) -> 3.1622777 | J6: Interop | K6: =((G6/C6)*100) -> 196.21723 | L6: =((H6/D6)*100) -> 125.83304 | M6: =((I6/E6)*100) -> 63.245553 | N6: Interop
B7: P99 (ms) | C7: =AVERAGE('1. Raw Data'!P8:P13) -> 2576.8333 | D7: =AVERAGE('1. Raw Data'!P26,'1. Raw Data'!P28:P31) -> 2390.8 | E7: =AVERAGE('1. Raw Data'!P44:P48) -> 1639.4 | F7: Interop | G7: =STDEV('1. Raw Data'!P8:P13) -> 2642.3578 | H7: =STDEV('1. Raw Data'!P26,'1. Raw Data'!P28:P31) -> 653.51947 | I7: =STDEV('1. Raw Data'!P44:P48) -> 455.46987 | J7: Interop | K7: =((G7/C7)*100) -> 102.54283 | L7: =((H7/D7)*100) -> 27.334761 | M7: =((I7/E7)*100) -> 27.782717 | N7: Idiomatic
B8: GC Time (ms) | C8: =AVERAGE('1. Raw Data'!Q8:Q13) -> 79.5 | D8: =AVERAGE('1. Raw Data'!Q26,'1. Raw Data'!Q28:Q31) -> 272.2 | E8: =AVERAGE('1. Raw Data'!Q44:Q48) -> 205.4 | F8: Java | G8: =STDEV('1. Raw Data'!Q8:Q13) -> 96.701086 | H8: =STDEV('1. Raw Data'!Q26,'1. Raw Data'!Q28:Q31) -> 186.50791 | I8: =STDEV('1. Raw Data'!Q44:Q48) -> 187.42012 | J8: Java | K8: =((G8/C8)*100) -> 121.63659 | L8: =((H8/D8)*100) -> 68.518703 | M8: =((I8/E8)*100) -> 91.246405 | N8: Idiomatic
B9: GC Collections | C9: =AVERAGE('1. Raw Data'!R8:R13) -> 2.5 | D9: =AVERAGE('1. Raw Data'!R26,'1. Raw Data'!R28:R31) -> 7 | E9: =AVERAGE('1. Raw Data'!R44:R48) -> 4.2 | F9: Java | G9: =STDEV('1. Raw Data'!R8:R13) -> 2.7386128 | H9: =STDEV('1. Raw Data'!R26,'1. Raw Data'!R28:R31) -> 1 | I9: =STDEV('1. Raw Data'!R44:R48) -> 2.4899799 | J9: Idiomatic | K9: =((G9/C9)*100) -> 109.54451 | L9: =((H9/D9)*100) -> 14.285714 | M9: =((I9/E9)*100) -> 59.285236 | N9: Idiomatic
A10: 1000 | B10: P95 (ms) | C10: =AVERAGE('1. Raw Data'!O14:O17,'1. Raw Data'!O19) -> 5078 | D10: =AVERAGE('1. Raw Data'!O32:O37) -> 4871.1667 | E10: =AVERAGE('1. Raw Data'!O50:O51,'1. Raw Data'!O53:O55) -> 5387.4 | F10: Idiomatic | G10: =STDEV('1. Raw Data'!O14:O17,'1. Raw Data'!O19) -> 765.54719 | H10: =STDEV('1. Raw Data'!O32:O37) -> 395.28846 | I10: =STDEV('1. Raw Data'!O50:O51,'1. Raw Data'!O53:O55) -> 656.77112 | J10: Idiomatic | K10: =(G10/C10)*100 -> 15.075762 | L10: =(H10/D10)*100 -> 8.1148622 | M10: =(I10/E10)*100 -> 12.190873 | N10: Idiomatic
B11: P99 (ms) | C11: =AVERAGE('1. Raw Data'!P14:P17,'1. Raw Data'!P19) -> 9958.8 | D11: =AVERAGE('1. Raw Data'!P32:P37) -> 10420.167 | E11: =AVERAGE('1. Raw Data'!P50:P51,'1. Raw Data'!P53:P55) -> 10048 | F11: Idiomatic | G11: =STDEV('1. Raw Data'!P14:P17,'1. Raw Data'!P19) -> 2210.2167 | H11: =STDEV('1. Raw Data'!P32:P37) -> 1453.144 | I11: =STDEV('1. Raw Data'!P50:P51,'1. Raw Data'!P53:P55) -> 514.28737 | J11: Interop | K11: =(G11/C11)*100 -> 22.193604 | L11: =(H11/D11)*100 -> 13.945496 | M11: =(I11/E11)*100 -> 5.1183058 | N11: Interop
B12: GC Time (ms) | C12: =AVERAGE('1. Raw Data'!Q14:Q17,'1. Raw Data'!Q19) -> 307 | D12: =AVERAGE('1. Raw Data'!Q32:Q37) -> 788 | E12: =AVERAGE('1. Raw Data'!Q50:Q51,'1. Raw Data'!Q53:Q55) -> 822.6 | F12: Java | G12: =STDEV('1. Raw Data'!Q14:Q17,'1. Raw Data'!Q19) -> 447.87052 | H12: =STDEV('1. Raw Data'!Q32:Q37) -> 660.67814 | I12: =STDEV('1. Raw Data'!Q50:Q51,'1. Raw Data'!Q53:Q55) -> 550.68621 | J12: Java | K12: =(G12/C12)*100 -> 145.88616 | L12: =(H12/D12)*100 -> 83.842403 | M12: =(I12/E12)*100 -> 66.944591 | N12: Interop
B13: GC Collections | C13: =AVERAGE('1. Raw Data'!R14:R17,'1. Raw Data'!R19) -> 4.6 | D13: =AVERAGE('1. Raw Data'!R32:R37) -> 10.666667 | E13: =AVERAGE('1. Raw Data'!R50:R51,'1. Raw Data'!R53:R55) -> 10.6 | F13: Java | G13: =STDEV('1. Raw Data'!R14:R17,'1. Raw Data'!R19) -> 6.3087241 | H13: =STDEV('1. Raw Data'!R32:R37) -> 8.3586283 | I13: =STDEV('1. Raw Data'!R50:R51,'1. Raw Data'!R53:R55) -> 6.1073726 | J13: Interop | K13: =(G13/C13)*100 -> 137.14618 | L13: =(H13/D13)*100 -> 78.36214 | M13: =(I13/E13)*100 -> 57.616723 | N13: Interop

Sheet 4. Performance Analysis
A1: Load | B1: Metric | C1: Java AVG (tab 2) | D1: Idiomatic AVG (tab 2) | E1: Interop AVG (tab 2) | F1: Best | G1: Δ | H1: Dimension
A2: 100 | B2: P95 (ms) | C2: =AVERAGE('1. Raw Data'!O2:O7) -> 2.5 | D2: =AVERAGE('1. Raw Data'!O20:O25) -> 2.6666667 | E2: =AVERAGE('1. Raw Data'!O38:O43) -> 2.6666667 | F2: DRAW | G2: 0 | H2: P95 Latency
B3: P99 (ms) | C3: =AVERAGE('1. Raw Data'!P2:P7) -> 4 | D3: =AVERAGE('1. Raw Data'!P20:P25) -> 4 | E3: =AVERAGE('1. Raw Data'!P38:P43) -> 4 | F3: DRAW | G3: 0 | H3: P99 Latency
B4: GC Time (ms) | C4: =AVERAGE('1. Raw Data'!Q2:Q7) -> 11 | D4: =AVERAGE('1. Raw Data'!Q20:Q25) -> 18.5 | E4: =AVERAGE('1. Raw Data'!Q38:Q43) -> 17.666667 | F4: Java | G4: =(D4-C4)/C4 -> 0.68181818 | H4: GC Overhead
B5: GC Collections | C5: =AVERAGE('1. Raw Data'!R2:R7) -> 0.66666667 | D5: =AVERAGE('1. Raw Data'!R20:R25) -> 1.1666667 | E5: =AVERAGE('1. Raw Data'!R38:R43) -> 1 | F5: Java | G5: =(D5-C5)/C5 -> 0.75 | H5: GC Overhead
A6: 500 | B6: P95 (ms) | C6: =AVERAGE('1. Raw Data'!O7:O12) -> 957 | D6: =AVERAGE('1. Raw Data'!O26,'1. Raw Data'!O28:O31) -> 151 | E6: =AVERAGE('1. Raw Data'!O44:O48) -> 5 | F6: Interop | G6: =(C6-E6)/E6 -> 190.4 | H6: P95 Latency
B7: P99 (ms) | C7: =AVERAGE('1. Raw Data'!P8:P13) -> 2576.8333 | D7: =AVERAGE('1. Raw Data'!P26,'1. Raw Data'!P28:P31) -> 2390.8 | E7: =AVERAGE('1. Raw Data'!P44:P48) -> 1639.4 | F7: Interop | G7: =(C7-E7)/E7 -> 0.57181489 | H7: P99 Latency
B8: GC Time (ms) | C8: =AVERAGE('1. Raw Data'!Q8:Q13) -> 79.5 | D8: =AVERAGE('1. Raw Data'!Q26,'1. Raw Data'!Q28:Q31) -> 272.2 | E8: =AVERAGE('1. Raw Data'!Q44:Q48) -> 205.4 | F8: Java | G8: =(D8-C8)/C8 -> 2.4238994 | H8: GC Overhead
B9: GC Collections | C9: =AVERAGE('1. Raw Data'!R8:R13) -> 2.5 | D9: =AVERAGE('1. Raw Data'!R26,'1. Raw Data'!R28:R31) -> 7 | E9: =AVERAGE('1. Raw Data'!R44:R48) -> 4.2 | F9: Java | G9: =(D9-C9)/C9 -> 1.8 | H9: GC Overhead
A10: 1000 | B10: P95 (ms) | C10: =AVERAGE('1. Raw Data'!O14:O17,'1. Raw Data'!O19) -> 5078 | D10: =AVERAGE('1. Raw Data'!O32:O37) -> 4871.1667 | E10: =AVERAGE('1. Raw Data'!O50:O51,'1. Raw Data'!O53:O55) -> 5387.4 | F10: Idiomatic | G10: =(E10-D10)/D10 -> 0.10597735 | H10: P95 Latency
B11: P99 (ms) | C11: =AVERAGE('1. Raw Data'!P14:P17,'1. Raw Data'!P19) -> 9958.8 | D11: =AVERAGE('1. Raw Data'!P32:P37) -> 10420.167 | E11: =AVERAGE('1. Raw Data'!P50:P51,'1. Raw Data'!P53:P55) -> 10048 | F11: Java | G11: =(D11-C11)/C11 -> 0.046327536 | H11: P99 Latency
B12: GC Time (ms) | C12: =AVERAGE('1. Raw Data'!Q14:Q17,'1. Raw Data'!Q19) -> 307 | D12: =AVERAGE('1. Raw Data'!Q32:Q37) -> 788 | E12: =AVERAGE('1. Raw Data'!Q50:Q51,'1. Raw Data'!Q53:Q55) -> 822.6 | F12: Java | G12: =(E12-C12)/C12 -> 1.6794788 | H12: GC Overhead
B13: GC Collections | C13: =AVERAGE('1. Raw Data'!R14:R17,'1. Raw Data'!R19) -> 4.6 | D13: =AVERAGE('1. Raw Data'!R32:R37) -> 10.666667 | E13: =AVERAGE('1. Raw Data'!R50:R51,'1. Raw Data'!R53:R55) -> 10.6 | F13: Java | G13: =(D13-C13)/C13 -> 1.3188406 | H13: GC Overhead
