Workbook

Sheet 1. Raw Data
A1: IMPL | B1: Load | C1: Time of tests (min) | D1: Total Requests | E1: Success Requests | F1: Failed Requests | G1: Error Rate (%) | H1: Req/Sec | I1: Min (ms) | J1: Mean (ms) | K1: Max (ms) | L1: Stdard Deviation (ms) | M1: P50 (ms) | N1: P75 (ms) | O1: P95 (ms) | P1: P99 (ms) | Q1: GC Time (ms) | R1: GC Collections | S1: Heap Peak (GB) | T1: Heap Peak (%) | U1: CPU Peak (%) | V1: < 800ms | W1: 800-1200ms | X1: > 1200ms | Y1: < 800ms (%) | Z1: 800-1200ms (%) | AA1: > 1200ms (%) | AB1: Total Requests Prometheus | AC1: Delta Gatling Prometheus | AD1: Sync Status | AE1: Error Status | AF1: Timestamp
A2: Java | B2: 100 | C2: 5 | D2: 30000 | E2: 30000 | F2: 0 | G2: 0 | H2: 100 | I2: 0 | J2: 2 | K2: 90 | L2: 1 | M2: 2 | N2: 2 | O2: 3 | P2: 4 | Q2: 32 | R2: 2 | S2: 1.03 | T2: 17 | U2: 44.56 | V2: 30000 | W2: 0 | X2: 0 | Y2: 100 | Z2: 0 | AA2: 0 | AB2: 30088 | AC2: 88 | AD2: GOOD | AE2: EXCELLENT | AF2: 46150.244
J3: 2 | K3: 404 | L3: 8 | M3: 2 | O3: 2 | P3: 4 | Q3: 35 | R3: 2 | S3: 1 | T3: 16 | U3: 45.14 | V3: 30000 | W3: 0 | X3: 0 | Y3: 100 | Z3: 0 | AA3: 0 | AB3: 30081 | AC3: 81 | AD3: GOOD | AE3: EXCELLENT | AF3: 46150.254
J4: 2 | K4: 103 | L4: 2 | M4: 2 | O4: 2 | P4: 4 | Q4: 38 | R4: 2 | S4: 0.99 | T4: 16 | U4: 47.51 | V4: 30000 | W4: 0 | X4: 0 | Y4: 100 | Z4: 0 | AA4: 0 | AB4: 30077 | AC4: 77 | AD4: GOOD | AE4: EXCELLENT | AF4: 46150.263
J5: 2 | K5: 223 | L5: 3 | M5: 2 | O5: 3 | P5: 4 | Q5: 14 | R5: 1 | S5: 0.89 | T5: 14 | U5: 57.77 | V5: 30000 | W5: 0 | X5: 0 | Y5: 100 | Z5: 0 | AA5: 0 | AB5: 30080 | AC5: 80 | AD5: GOOD | AE5: EXCELLENT | AF5: 46150.271
J6: 1 | K6: 16 | L6: 1 | M6: 1 | O6: 2 | P6: 3 | Q6: 14 | R6: 1 | S6: 1.37 | T6: 22 | U6: 2.57 | V6: 30000 | W6: 0 | X6: 0 | Y6: 100 | Z6: 0 | AA6: 0 | AB6: 30077 | AC6: 77 | AD6: GOOD | AE6: EXCELLENT | AF6: 46150.279
J7: 2 | K7: 91 | L7: 1 | M7: 2 | O7: 2 | P7: 4 | Q7: 32 | R7: 2 | S7: 1 | T7: 16 | U7: 34.98 | V7: 30000 | W7: 0 | X7: 0 | Y7: 100 | Z7: 0 | AA7: 0 | AB7: 30087 | AC7: 87 | AD7: GOOD | AE7: EXCELLENT | AF7: 46150.289
B8: 500 | C8: 5 | D8: 150000 | E8: 150000 | F8: 0 | G8: 0 | H8: 500 | I8: 0 | J8: 61 | K8: 6623 | L8: 361 | M8: 1 | N8: 1 | O8: 17 | P8: 1991 | Q8: 329 | R8: 6 | S8: 2.38 | T8: 39 | U8: 66.15 | V8: 150000 | W8: 0 | X8: 0 | Y8: 100 | Z8: 0 | AA8: 0 | AB8: 150091 | AC8: 91 | AD8: EXCELLENT | AE8: EXCELLENT | AF8: 2026-05-09 08:40:37
J9: 89 | K9: 8120 | L9: 515 | O9: 110 | P9: 2812 | Q9: 74 | R9: 5 | S9: 2.35 | T9: 39 | U9: 67.96 | V9: 150000 | W9: 0 | X9: 0 | Y9: 100 | Z9: 0 | AA9: 0 | AB9: 150077 | AC9: 77 | AD9: EXCELLENT | AE9: EXCELLENT | AF9: 2026-05-09 08:54:34
J10: 84 | K10: 7271 | L10: 478 | O10: 28 | P10: 2920 | Q10: 83 | R10: 5 | S10: 2.34 | T10: 39 | U10: 67.17 | V10: 150000 | W10: 0 | X10: 0 | Y10: 100 | Z10: 0 | AA10: 0 | AB10: 150084 | AC10: 84 | AD10: EXCELLENT | AE10: EXCELLENT | AF10: 2026-05-09 09:08:08
J11: 70 | K11: 5876 | L11: 395 | O11: 24 | P11: 2181 | Q11: 131 | R11: 7 | S11: 2.36 | T11: 39 | U11: 65.04 | V11: 150000 | W11: 0 | X11: 0 | Y11: 100 | Z11: 0 | AA11: 0 | AB11: 150080 | AC11: 80 | AD11: EXCELLENT | AE11: EXCELLENT | AF11: 2026-05-09 09:22:44
J12: 28 | K12: 4995 | L12: 190 | O12: 2 | P12: 824 | Q12: 218 | R12: 5 | S12: 2.28 | T12: 38 | U12: 65.97 | V12: 150000 | W12: 0 | X12: 0 | Y12: 100 | Z12: 0 | AA12: 0 | AB12: 150078 | AC12: 78 | AD12: EXCELLENT | AE12: EXCELLENT | AF12: 2026-05-09 09:35:25
J13: 136 | K13: 9207 | L13: 689 | O13: 699 | P13: 3915 | Q13: 469 | R13: 6 | S13: 2.27 | T13: 37 | U13: 74.27 | V13: 150000 | W13: 0 | X13: 0 | Y13: 100 | Z13: 0 | AA13: 0 | AB13: 150082 | AC13: 82 | AD13: EXCELLENT | AE13: EXCELLENT | AF13: 2026-05-09 09:48:24
B14: 1000 | C14: 5 | D14: 300000 | E14: 299988 | F14: 12 | G14: 0 | H14: 1000 | I14: 0 | J14: 902 | K14: 20655 | L14: 2623 | M14: 1 | N14: 1 | O14: 6408 | P14: 13041 | Q14: 1340 | R14: 14 | S14: 2.33 | T14: 38 | U14: 77.8 | V14: 300000 | W14: 0 | X14: 0 | Y14: 100 | Z14: 0 | AA14: 0 | AB14: 300068 | AC14: 80 | AD14: EXCELLENT | AE14: EXCELLENT | AF14: 2026-05-13 18:08:11
E15: 300000 | F15: 0 | G15: 0 | H15: 1000 | J15: 563 | K15: 17454 | L15: 1899 | M15: 1 | N15: 1 | O15: 4672 | P15: 10176 | Q15: 622 | R15: 10 | S15: 2.39 | T15: 39 | U15: 78.58 | V15: 300000 | W15: 0 | X15: 0 | Y15: 100 | Z15: 0 | AA15: 0 | AB15: 300078 | AC15: 78 | AD15: EXCELLENT | AE15: EXCELLENT | AF15: 2026-05-13 18:21:32
E16: 300000 | F16: 0 | G16: 0 | H16: 1000 | J16: 932 | K16: 20307 | L16: 2559 | M16: 1 | N16: 1 | O16: 7891 | P16: 11604 | Q16: 1547 | R16: 16 | S16: 2.33 | T16: 38 | U16: 82.43 | V16: 300000 | W16: 0 | X16: 0 | Y16: 100 | Z16: 0 | AA16: 0 | AB16: 300080 | AC16: 80 | AD16: EXCELLENT | AE16: EXCELLENT | AF16: 2026-05-13 18:34:24
E17: 300000 | F17: 0 | G17: 0 | H17: 1000 | J17: 566 | K17: 17066 | L17: 1821 | M17: 1 | N17: 1 | O17: 4577 | P17: 9584 | Q17: 1398 | R17: 15 | S17: 2.33 | T17: 38 | U17: 78.4 | V17: 300000 | W17: 0 | X17: 0 | Y17: 100 | Z17: 0 | AA17: 0 | AB17: 300079 | AC17: 79 | AD17: EXCELLENT | AE17: EXCELLENT | AF17: 2026-05-13 18:48:01
E18: 300000 | F18: 0 | G18: 0 | H18: 1000 | J18: 606 | K18: 15992 | L18: 1919 | M18: 1 | N18: 1 | O18: 5767 | P18: 9148 | Q18: 1048 | R18: 13 | S18: 2.35 | T18: 39 | U18: 73.68 | V18: 300000 | W18: 0 | X18: 0 | Y18: 100 | Z18: 0 | AA18: 0 | AB18: 300081 | AC18: 81 | AD18: EXCELLENT | AE18: EXCELLENT | AF18: 2026-05-13 19:01:47
E19: 243970 | F19: 56030 | G19: 18.6 | H19: 857.14 | J19: 35817 | K19: 182679 | L19: 40646 | M19: 20374 | N19: 60544 | O19: 114468 | P19: 141789 | Q19: 9527 | R19: 49 | S19: 0.8 | T19: 13 | U19: 83.23 | V19: 300000 | W19: 0 | X19: 0 | Y19: 100 | Z19: 0 | AA19: 0 | AB19: 249707 | AC19: 5737 | AD19: WARNING | AE19: HIGH | AF19: 2026-05-13 19:15:52
A20: Clojure-Idiomatic | B20: 100 | C20: 5 | D20: 30000 | E20: 30000 | F20: 0 | G20: 0 | H20: 100 | I20: 0 | J20: 2 | K20: 99 | L20: 2 | M20: 2 | N20: 2 | O20: 2 | P20: 4 | Q20: 31 | R20: 2 | S20: 0.99 | T20: 16 | U20: 36.07 | V20: 30000 | W20: 0 | X20: 0 | Y20: 100 | Z20: 0 | AA20: 0 | AB20: 30077 | AC20: 77 | AD20: GOOD | AE20: EXCELLENT | AF20: 2026-05-08 13:22:52
K21: 199 | L21: 3 | M21: 2 | Q21: 16 | R21: 1 | S21: 1 | T21: 16 | U21: 41 | V21: 30000 | W21: 0 | X21: 0 | Y21: 100 | Z21: 0 | AA21: 0 | AB21: 30078 | AC21: 78 | AD21: GOOD | AE21: EXCELLENT | AF21: 2026-05-08 13:36:32
K22: 140 | L22: 2 | M22: 2 | Q22: 32 | R22: 2 | S22: 0.98 | T22: 16 | U22: 49.11 | V22: 30000 | W22: 0 | X22: 0 | Y22: 100 | Z22: 0 | AA22: 0 | AB22: 30078 | AC22: 78 | AD22: GOOD | AE22: EXCELLENT | AF22: 2026-05-08 13:50:48
K23: 89 | L23: 1 | M23: 1 | Q23: 16 | R23: 1 | S23: 0.92 | T23: 15 | U23: 43.36 | V23: 30000 | W23: 0 | X23: 0 | Y23: 100 | Z23: 0 | AA23: 0 | AB23: 30078 | AC23: 78 | AD23: GOOD | AE23: EXCELLENT | AF23: 2026-05-08 14:04:05
K24: 108 | L24: 2 | M24: 1 | Q24: 29 | R24: 2 | S24: 0.85 | T24: 14 | U24: 45.85 | V24: 30000 | W24: 0 | X24: 0 | Y24: 100 | Z24: 0 | AA24: 0 | AB24: 30077 | AC24: 77 | AD24: GOOD | AE24: EXCELLENT | AF24: 2026-05-08 14:16:56
K25: 80 | L25: 1 | M25: 2 | Q25: 0 | R25: 0 | S25: 1.59 | T25: 26 | U25: 37.63 | V25: 30000 | W25: 0 | X25: 0 | Y25: 100 | Z25: 0 | AA25: 0 | AB25: 30077 | AC25: 77 | AD25: GOOD | AE25: EXCELLENT | AF25: 2026-05-08 14:30:12
B26: 500 | C26: 5 | D26: 150000 | E26: 150000 | F26: 0 | G26: 0 | H26: 500 | I26: 0 | J26: 29 | K26: 3799 | L26: 190 | M26: 1 | N26: 1 | O26: 2 | P26: 994 | Q26: 161 | R26: 6 | S26: 2.37 | T26: 39 | U26: 66.12 | V26: 150000 | W26: 0 | X26: 0 | Y26: 100 | Z26: 0 | AA26: 0 | AB26: 150077 | AC26: 77 | AD26: EXCELLENT | AE26: EXCELLENT | AF26: 2026-05-09 12:50:16
J27: 50 | K27: 5508 | L27: 297 | O27: 15 | P27: 1593 | Q27: 103 | R27: 7 | S27: 2.3 | T27: 38 | U27: 68.17 | V27: 150000 | W27: 0 | X27: 0 | Y27: 100 | Z27: 0 | AA27: 0 | AB27: 150078 | AC27: 78 | AD27: EXCELLENT | AE27: EXCELLENT | AF27: 2026-05-09 13:03:18
J28: 255 | K28: 12910 | L28: 1036 | O28: 2104 | P28: 5635 | Q28: 474 | R28: 8 | S28: 2.39 | T28: 39 | U28: 87.99 | V28: 150000 | W28: 0 | X28: 0 | Y28: 100 | Z28: 0 | AA28: 0 | AB28: 150078 | AC28: 78 | AD28: EXCELLENT | AE28: EXCELLENT | AF28: 2026-05-09 13:16:42
J29: 98 | K29: 8105 | L29: 533 | O29: 272 | P29: 2891 | Q29: 124 | R29: 6 | S29: 2.27 | T29: 37 | U29: 69.53 | V29: 150000 | W29: 0 | X29: 0 | Y29: 100 | Z29: 0 | AA29: 0 | AB29: 150077 | AC29: 77 | AD29: EXCELLENT | AE29: EXCELLENT | AF29: 2026-05-09 13:29:10
J30: 58 | K30: 5524 | L30: 344 | O30: 15 | P30: 1895 | Q30: 129 | R30: 7 | S30: 2.36 | T30: 39 | U30: 67.07 | V30: 150000 | W30: 0 | X30: 0 | Y30: 100 | Z30: 0 | AA30: 0 | AB30: 150077 | AC30: 77 | AD30: EXCELLENT | AE30: EXCELLENT | AF30: 2026-05-09 13:42:10
J31: 96 | K31: 8204 | L31: 526 | O31: 211 | P31: 2872 | Q31: 115 | R31: 6 | S31: 2.35 | T31: 39 | U31: 70.78 | V31: 150000 | W31: 0 | X31: 0 | Y31: 100 | Z31: 0 | AA31: 0 | AB31: 150079 | AC31: 79 | AD31: EXCELLENT | AE31: EXCELLENT | AF31: 2026-05-09 13:55:21
B32: 1000 | C32: 5 | D32: 300000 | E32: 300000 | F32: 0 | G32: 0 | H32: 1000 | I32: 0 | J32: 661 | K32: 14315 | L32: 1929 | M32: 1 | N32: 1 | O32: 5320 | P32: 9602 | Q32: 1129 | R32: 16 | S32: 2.32 | T32: 38 | U32: 82.95 | V32: 300000 | W32: 0 | X32: 0 | Y32: 100 | Z32: 0 | AA32: 0 | AB32: 300078 | AC32: 78 | AD32: EXCELLENT | AE32: EXCELLENT | AF32: 2026-05-13 20:31:49
E33: 298059 | F33: 1941 | G33: 0.6 | H33: 1000 | J33: 2854 | K33: 60002 | L33: 6688 | M33: 1 | N33: 1080 | O33: 17889 | P33: 26109 | Q33: 3038 | R33: 25 | S33: 0.95 | T33: 15 | U33: 68.33 | V33: 300000 | W33: 0 | X33: 0 | Y33: 100 | Z33: 0 | AA33: 0 | AB33: 299087 | AC33: 1028 | AD33: GOOD | AE33: GOOD | AF33: 2026-05-13 20:45:04
E34: 299998 | F34: 2 | G34: 0 | H34: 1000 | J34: 2671 | K34: 60005 | L34: 5419 | M34: 1 | N34: 3381 | O34: 17349 | P34: 22905 | Q34: 2165 | R34: 21 | S34: 0.95 | T34: 15 | U34: 80.56 | V34: 300000 | W34: 0 | X34: 0 | Y34: 100 | Z34: 0 | AA34: 0 | AB34: 300079 | AC34: 81 | AD34: EXCELLENT | AE34: EXCELLENT | AF34: 2026-05-13 20:58:10
E35: 300000 | F35: 0 | G35: 0 | H35: 1000 | J35: 889 | K35: 15963 | L35: 2512 | M35: 1 | N35: 1 | O35: 7788 | P35: 11194 | Q35: 1186 | R35: 16 | S35: 2.33 | T35: 38 | U35: 81.33 | V35: 300000 | W35: 0 | X35: 0 | Y35: 100 | Z35: 0 | AA35: 0 | AB35: 300079 | AC35: 79 | AD35: EXCELLENT | AE35: EXCELLENT | AF35: 2026-05-13 21:11:25
E36: 300000 | F36: 0 | G36: 0 | H36: 1000 | J36: 974 | K36: 22783 | L36: 2696 | M36: 1 | N36: 1 | O36: 7992 | P36: 12361 | Q36: 1676 | R36: 18 | S36: 2.35 | T36: 39 | U36: 83.33 | V36: 300000 | W36: 0 | X36: 0 | Y36: 100 | Z36: 0 | AA36: 0 | AB36: 300079 | AC36: 79 | AD36: EXCELLENT | AE36: EXCELLENT | AF36: 2026-05-13 21:25:12
E37: 237007 | F37: 62993 | G37: 20.9 | H37: 874.64 | J37: 33269 | K37: 172481 | L37: 39169 | M37: 16191 | N37: 60142 | O37: 113354 | P37: 129507 | Q37: 11308 | R37: 57 | S37: 1.6 | T37: 26 | U37: 76.06 | V37: 300000 | W37: 0 | X37: 0 | Y37: 100 | Z37: 0 | AA37: 0 | AB37: 243910 | AC37: 6903 | AD37: WARNING | AE37: HIGH | AF37: 2026-05-13 21:39:24
A38: Clojure-Interop | B38: 100 | C38: 5 | D38: 30000 | E38: 30000 | F38: 0 | G38: 0 | H38: 100 | I38: 0 | J38: 2 | K38: 198 | L38: 3 | M38: 2 | N38: 2 | O38: 2 | P38: 4 | Q38: 34 | R38: 2 | S38: 0.84 | T38: 14 | U38: 44.85 | V38: 30000 | W38: 0 | X38: 0 | Y38: 100 | Z38: 0 | AA38: 0 | AB38: 30077 | AC38: 77 | AD38: GOOD | AE38: EXCELLENT | AF38: 2026-05-08 16:02:58
J39: 2 | K39: 127 | L39: 2 | M39: 2 | O39: 2 | P39: 4 | Q39: 0 | R39: 0 | S39: 1.6 | T39: 26 | U39: 49.61 | V39: 30000 | W39: 0 | X39: 0 | Y39: 100 | Z39: 0 | AA39: 0 | AB39: 30078 | AC39: 78 | AD39: GOOD | AE39: EXCELLENT | AF39: 2026-05-08 16:19:37
J40: 2 | K40: 102 | L40: 2 | M40: 2 | O40: 2 | P40: 4 | Q40: 33 | R40: 2 | S40: 1.06 | T40: 17 | U40: 39.95 | V40: 30000 | W40: 0 | X40: 0 | Y40: 100 | Z40: 0 | AA40: 0 | AB40: 30079 | AC40: 79 | AD40: GOOD | AE40: EXCELLENT | AF40: 2026-05-08 16:32:49
...

Sheet 2. General Statistical Analysis
A1: Load | B1: Metric | C1: Java AVG | D1: Idiomatic AVG | E1: Interop AVG | F1: Best AVG | G1: Java STD DEV | H1: Idiomatic STD DEV | I1: Interop STD DEV | J1: Best STD DEV | K1: Java CV% | L1: Idiomatic CV% | M1: Interop CV% | N1: Best CV%
A2: 100 | B2: P95 (ms) | C2: =AVERAGE('1. Raw Data'!O2:O7) -> 2.3333333 | D2: =AVERAGE('1. Raw Data'!O20:O25) -> 2 | E2: =AVERAGE('1. Raw Data'!O38:O43) -> 2.1666667 | F2: Idiomatic | G2: =STDEV('1. Raw Data'!O2:O7) -> 0.51639778 | H2: =STDEV('1. Raw Data'!O20:O25) -> #DIV/0! | I2: =STDEV('1. Raw Data'!O38:O43) -> 0.40824829 | J2: Interop | K2: =(G2/C2)*100 -> 22.131333 | L2: =(H2/D2)*100 -> #DIV/0! | M2: =(I2/E2)*100 -> 18.842229 | N2: Idiomatic
B3: P99 (ms) | C3: =AVERAGE('1. Raw Data'!P2:P7) -> 3.8333333 | D3: =AVERAGE('1. Raw Data'!P20:P25) -> 4 | E3: =AVERAGE('1. Raw Data'!P38:P43) -> 3.8333333 | F3: DRAW | G3: =STDEV('1. Raw Data'!P2:P7) -> 0.40824829 | H3: =STDEV('1. Raw Data'!P20:P25) -> #DIV/0! | I3: =STDEV('1. Raw Data'!P38:P43) -> 0.40824829 | J3: DRAW | K3: =(G3/C3)*100 -> 10.649955 | L3: =(H3/D3)*100 -> #DIV/0! | M3: =(I3/E3)*100 -> 10.649955 | N3: Idiomatic
B4: GC Time (ms) | C4: =AVERAGE('1. Raw Data'!Q2:Q7) -> 27.5 | D4: =AVERAGE('1. Raw Data'!Q20:Q25) -> 20.666667 | E4: =AVERAGE('1. Raw Data'!Q38:Q43) -> 21.5 | F4: Idiomatic | G4: =STDEV('1. Raw Data'!Q2:Q7) -> 10.691118 | H4: =STDEV('1. Raw Data'!Q20:Q25) -> 12.452577 | I4: =STDEV('1. Raw Data'!Q38:Q43) -> 14.039231 | J4: Java | K4: =(G4/C4)*100 -> 38.876792 | L4: =(H4/D4)*100 -> 60.254403 | M4: =(I4/E4)*100 -> 65.298748 | N4: Java
B5: GC Collections | C5: =AVERAGE('1. Raw Data'!R2:R7) -> 1.6666667 | D5: =AVERAGE('1. Raw Data'!R20:R25) -> 1.3333333 | E5: =AVERAGE('1. Raw Data'!R38:R43) -> 1.3333333 | F5: DRAW | G5: =STDEV('1. Raw Data'!R2:R7) -> 0.51639778 | H5: =STDEV('1. Raw Data'!R20:R25) -> 0.81649658 | I5: =STDEV('1. Raw Data'!R38:R43) -> 0.81649658 | J5: Java | K5: =(G5/C5)*100 -> 30.983867 | L5: =(H5/D5)*100 -> 61.237244 | M5: =(I5/E5)*100 -> 61.237244 | N5: Java
A6: 500 | B6: P95 (ms) | C6: =AVERAGE('1. Raw Data'!O8:O13) -> 146.66667 | D6: =AVERAGE('1. Raw Data'!O26:O31) -> 436.5 | E6: =AVERAGE('1. Raw Data'!O44:O49) -> 4483.6667 | F6: Java | G6: =STDEV('1. Raw Data'!O8:O13) -> 273.23519 | H6: =STDEV('1. Raw Data'!O26:O31) -> 824.93412 | I6: =STDEV('1. Raw Data'!O44:O49) -> 10456.124 | J6: Java | K6: =(G6/C6)*100 -> 186.29672 | L6: =(H6/D6)*100 -> 188.98834 | M6: =(I6/E6)*100 -> 233.20476 | N6: Java
B7: P99 (ms) | C7: =AVERAGE('1. Raw Data'!P8:P13) -> 2440.5 | D7: =AVERAGE('1. Raw Data'!P26:P31) -> 2646.6667 | E7: =AVERAGE('1. Raw Data'!P44:P49) -> 6789.5 | F7: java | G7: =STDEV('1. Raw Data'!P8:P13) -> 1041.5897 | H7: =STDEV('1. Raw Data'!P26:P31) -> 1639.9472 | I7: =STDEV('1. Raw Data'!P44:P49) -> 11505.214 | J7: Java | K7: =(G7/C7)*100 -> 42.679357 | L7: =(H7/D7)*100 -> 61.962739 | M7: =(I7/E7)*100 -> 169.45598 | N7: Java
B8: GC Time (ms) | C8: =AVERAGE('1. Raw Data'!Q8:Q13) -> 217.33333 | D8: =AVERAGE('1. Raw Data'!Q26:Q31) -> 184.33333 | E8: =AVERAGE('1. Raw Data'!Q44:Q49) -> 360.5 | F8: Idiomatic | G8: =STDEV('1. Raw Data'!Q8:Q13) -> 156.10851 | H8: =STDEV('1. Raw Data'!Q26:Q31) -> 143.23082 | I8: =STDEV('1. Raw Data'!Q44:Q49) -> 292.61288 | J8: Idiomatic | K8: =(G8/C8)*100 -> 71.829069 | L8: =(H8/D8)*100 -> 77.70207 | M8: =(I8/E8)*100 -> 81.168623 | N8: Java
B9: GC Collections | C9: =AVERAGE('1. Raw Data'!R8:R13) -> 5.6666667 | D9: =AVERAGE('1. Raw Data'!R26:R31) -> 6.6666667 | E9: =AVERAGE('1. Raw Data'!R44:R49) -> 6.5 | F9: Interop | G9: =STDEV('1. Raw Data'!R8:R13) -> 0.81649658 | H9: =STDEV('1. Raw Data'!R26:R31) -> 0.81649658 | I9: =STDEV('1. Raw Data'!R44:R49) -> 1.7606817 | J9: DRAW | K9: =(G9/C9)*100 -> 14.408763 | L9: =(H9/D9)*100 -> 12.247449 | M9: =(I9/E9)*100 -> 27.087411 | N9: Idiomatic
A10: 1000 | B10: P95 (ms) | C10: =AVERAGE('1. Raw Data'!O14:O19) -> 23963.833 | D10: =AVERAGE('1. Raw Data'!O32:O37) -> 28282 | E10: =AVERAGE('1. Raw Data'!O50:O55) -> 22669.5 | F10: Interop | G10: =STDEV('1. Raw Data'!O14:O19) -> 44354.698 | H10: =STDEV('1. Raw Data'!O32:O37) -> 42008.884 | I10: =STDEV('1. Raw Data'!O50:O55) -> 41546.384 | J10: Interop | K10: =(G10/C10)*100 -> 185.09016 | L10: =(H10/D10)*100 -> 148.53576 | M10: =(I10/E10)*100 -> 183.26996 | N10: Idiomatic
B11: P99 (ms) | C11: =AVERAGE('1. Raw Data'!P14:P19) -> 32557 | D11: =AVERAGE('1. Raw Data'!P32:P37) -> 35279.667 | E11: =AVERAGE('1. Raw Data'!P50:P55) -> 31778.167 | F11: Interop | G11: =STDEV('1. Raw Data'!P14:P19) -> 53531.638 | H11: =STDEV('1. Raw Data'!P32:P37) -> 46649.225 | I11: =STDEV('1. Raw Data'!P50:P55) -> 48822.189 | J11: Idiomatic | K11: =(G11/C11)*100 -> 164.42436 | L11: =(H11/D11)*100 -> 132.22694 | M11: =(I11/E11)*100 -> 153.63438 | N11: Idiomatic
B12: GC Time (ms) | C12: =AVERAGE('1. Raw Data'!Q14:Q19) -> 2580.3333 | D12: =AVERAGE('1. Raw Data'!Q32:Q37) -> 3417 | E12: =AVERAGE('1. Raw Data'!Q50:Q55) -> 2088.1667 | F12: Interop | G12: =STDEV('1. Raw Data'!Q14:Q19) -> 3418.8714 | H12: =STDEV('1. Raw Data'!Q32:Q37) -> 3929.9469 | I12: =STDEV('1. Raw Data'!Q50:Q55) -> 2652.7738 | J12: Interop | K12: =(G12/C12)*100 -> 132.49728 | L12: =(H12/D12)*100 -> 115.01161 | M12: =(I12/E12)*100 -> 127.03841 | N12: Idiomatic
B13: GC Collections | C13: =AVERAGE('1. Raw Data'!R14:R19) -> 19.5 | D13: =AVERAGE('1. Raw Data'!R32:R37) -> 25.5 | E13: =AVERAGE('1. Raw Data'!R50:R55) -> 16 | F13: Interop | G13: =STDEV('1. Raw Data'!R14:R19) -> 14.597945 | H13: =STDEV('1. Raw Data'!R32:R37) -> 15.808226 | I13: =STDEV('1. Raw Data'!R50:R55) -> 8.8769364 | J13: Interop | K13: =(G13/C13)*100 -> 74.861257 | L13: =(H13/D13)*100 -> 61.993042 | M13: =(I13/E13)*100 -> 55.480853 | N13: Interop

Sheet 3. Z-Score
A1: IMPL | B1: Load | C1: P95 (ms) | D1: Average | E1: Standard Deviation | F1: Z-Score | G1: Outlier
A2: Java | B2: 100 | C2: 3 | D2: =AVERAGE(C2:C7) -> 2.3333333 | E2: =STDEV(C2:C7) -> 0.51639778 | F2: =(C2-D2)/E2 -> 1.2909944 | G2: =ABS(F2)>2 -> FALSE
C3: 2 | F3: =(C3-D2)/E2 -> -0.64549722 | G3: =ABS(F3)>2 -> FALSE
C4: 2 | F4: =(C4-D2)/E2 -> -0.64549722 | G4: =ABS(F4)>2 -> FALSE
C5: 3 | F5: =(C5-D2)/E2 -> 1.2909944 | G5: =ABS(F5)>2 -> FALSE
C6: 2 | F6: =(C6-D2)/E2 -> -0.64549722 | G6: =ABS(F6)>2 -> FALSE
C7: 2 | F7: =(C7-D2)/E2 -> -0.64549722 | G7: =ABS(F7)>2 -> FALSE
B8: 500 | C8: 17 | D8: =AVERAGE(C8:C13) -> 146.66667 | E8: =STDEV(C8:C13) -> 273.23519 | F8: =(C8-D8)/E8 -> -0.47456065 | G8: =ABS(F8)>2 -> FALSE
C9: 110 | F9: =(C9-D8)/E8 -> -0.13419453 | G9: =ABS(F9)>2 -> FALSE
C10: 28 | F10: =(C10-D8)/E8 -> -0.43430229 | G10: =ABS(F10)>2 -> FALSE
C11: 24 | F11: =(C11-D8)/E8 -> -0.44894169 | G11: =ABS(F11)>2 -> FALSE
C12: 2 | F12: =(C12-D8)/E8 -> -0.52945841 | G12: =ABS(F12)>2 -> FALSE
C13: 699 | F13: =(C13-D8)/E8 -> 2.0214576 | G13: =ABS(F13)>2 -> TRUE
B14: 1000 | C14: 6408 | D14: =AVERAGE(C14:C18) -> 5863 | E14: =STDEV(C14:C18) -> 1368.5121 | F14: =(C14-D14)/E14 -> 0.39824272 | G14: =ABS(F14)>2 -> FALSE
C15: 4672 | F15: =(C15-D14)/E14 -> -0.87028822 | G15: =ABS(F15)>2 -> FALSE
C16: 7891 | F16: =(C16-D14)/E14 -> 1.4819014 | G16: =ABS(F16)>2 -> FALSE
C17: 4577 | F17: =(C17-D14)/E14 -> -0.93970667 | G17: =ABS(F17)>2 -> FALSE
C18: 5767 | F18: =(C18-D14)/E14 -> -0.070149176 | G18: =ABS(F18)>2 -> FALSE
A19: Clojure-Idiomatic | B19: 100 | C19: 2 | D19: =AVERAGE(C19:C24) -> 2 | E19: =STDEV(C19:C24) -> 0 | F19: undefined | G19: FALSE
C20: 2 | F20: undefined | G20: FALSE
C21: 2 | F21: undefined | G21: FALSE
C22: 2 | F22: undefined | G22: FALSE
C23: 2 | F23: undefined | G23: FALSE
C24: 2 | F24: undefined | G24: FALSE
B25: 500 | C25: 2 | D25: =AVERAGE(C25:C30) -> 436.5 | E25: =STDEV(C25:C30) -> 824.93412 | F25: =(C25-D25)/E25 -> -0.52670873 | G25: =ABS(F25)>2 -> FALSE
C26: 15 | F26: =(C26-D25)/E25 -> -0.51094989 | G26: =ABS(F26)>2 -> FALSE
C27: 2104 | F27: =(C27-D25)/E25 -> 2.0213735 | G27: =ABS(F27)>2 -> TRUE
C28: 272 | F28: =(C28-D25)/E25 -> -0.19940986 | G28: =ABS(F28)>2 -> FALSE
C29: 15 | F29: =(C29-D25)/E25 -> -0.51094989 | G29: =ABS(F29)>2 -> FALSE
C30: 211 | F30: =(C30-D25)/E25 -> -0.27335516 | G30: =ABS(F30)>2 -> FALSE
B31: 1000 | C31: 5320 | D31: =AVERAGE(C31:C34) -> 9612.25 | E31: =STDEV(C31:C34) -> 5298.8618 | F31: =(C31-D31)/E31 -> -0.81003245 | G31: =ABS(F31)>2 -> FALSE
C32: 17349 | F32: =(C32-D31)/E31 -> 1.4600777 | G32: =ABS(F32)>2 -> FALSE
C33: 7788 | F33: =(C33-D31)/E31 -> -0.34427205 | G33: =ABS(F33)>2 -> FALSE
C34: 7992 | F34: =(C34-D31)/E31 -> -0.30577321 | G34: =ABS(F34)>2 -> FALSE
A35: Clojure-Interop | B35: 100 | C35: 2 | D35: =AVERAGE(C35:C40) -> 2.1666667 | E35: =STDEV(C35:C40) -> 0.40824829 | F35: =(C35-D35)/E35 -> -0.40824829 | G35: =ABS(F35)>2 -> FALSE
C36: 2 | F36: =(C36-D35)/E35 -> -0.40824829 | G36: =ABS(F36)>2 -> FALSE
C37: 2 | F37: =(C37-D35)/E35 -> -0.40824829 | G37: =ABS(F37)>2 -> FALSE
C38: 3 | F38: =(C38-D35)/E35 -> 2.0412415 | G38: =ABS(F38)>2 -> TRUE
C39: 2 | F39: =(C39-D35)/E35 -> -0.40824829 | G39: =ABS(F39)>2 -> FALSE
C40: 2 | F40: =(C40-D35)/E35 -> -0.40824829 | G40: =ABS(F40)>2 -> FALSE
...

Sheet 4. Statistical Analysis Without
A1: Load | B1: Metric | C1: Java AVG | D1: Idiomatic AVG | E1: Interop AVG | F1: Best AVG | G1: Java STD DEV | H1: Idiomatic STD DEV | I1: Interop STD DEV | J1: Best STD DEV | K1: Java CV% | L1: Idiomatic CV% | M1: Interop CV% | N1: Best CV%
A2: 100 | B2: P95 (ms) | C2: =AVERAGE('1. Raw Data'!O2:O7) -> 2.3333333 | D2: =AVERAGE('1. Raw Data'!O20:O25) -> 2 | E2: =AVERAGE('1. Raw Data'!O38:O40,'1. Raw Data'!O42:O43) -> 2 | F2: DRAW | G2: =STDEV('1. Raw Data'!O2:O7) -> 0.51639778 | H2: =STDEV('1. Raw Data'!O20:O25) -> #DIV/0! | I2: =STDEV('1. Raw Data'!O38:O40,'1. Raw Data'!O42:O43) -> 0 | J2: Idiomatic | K2: =((G2/C2)*100) -> 22.131333 | L2: =((H2/D2)*100) -> #DIV/0! | M2: =((I2/E2)*100) -> 0 | N2: DRAW
B3: P99 (ms) | C3: =AVERAGE('1. Raw Data'!P2:P7) -> 3.8333333 | D3: =AVERAGE('1. Raw Data'!P20:P25) -> 4 | E3: =AVERAGE('1. Raw Data'!P38:P40,'1. Raw Data'!P42:P43) -> 3.8 | F3: Interop | G3: =STDEV('1. Raw Data'!P2:P7) -> 0.40824829 | H3: =STDEV('1. Raw Data'!P20:P25) -> #DIV/0! | I3: =STDEV('1. Raw Data'!P38:P40,'1. Raw Data'!P42:P43) -> 0.4472136 | J3: DRAW | K3: =((G3/C3)*100) -> 10.649955 | L3: =((H3/D3)*100) -> #DIV/0! | M3: =((I3/E3)*100) -> 11.768779 | N3: idiomatic
B4: GC Time (ms) | C4: =AVERAGE('1. Raw Data'!Q2:Q7) -> 27.5 | D4: =AVERAGE('1. Raw Data'!Q20:Q25) -> 20.666667 | E4: =AVERAGE('1. Raw Data'!Q38:Q40,'1. Raw Data'!Q42:Q43) -> 22.6 | F4: Idiomatic | G4: =STDEV('1. Raw Data'!Q2:Q7) -> 10.691118 | H4: =STDEV('1. Raw Data'!Q20:Q25) -> 12.452577 | I4: =STDEV('1. Raw Data'!Q38:Q40,'1. Raw Data'!Q42:Q43) -> 15.404545 | J4: Java | K4: =((G4/C4)*100) -> 38.876792 | L4: =((H4/D4)*100) -> 60.254403 | M4: =((I4/E4)*100) -> 68.161703 | N4: Java
B5: GC Collections | C5: =AVERAGE('1. Raw Data'!R2:R7) -> 1.6666667 | D5: =AVERAGE('1. Raw Data'!R20:R25) -> 1.3333333 | E5: =AVERAGE('1. Raw Data'!R38:R40,'1. Raw Data'!R42:R43) -> 1.4 | F5: Idiomatic | G5: =STDEV('1. Raw Data'!R2:R7) -> 0.51639778 | H5: =STDEV('1. Raw Data'!R20:R25) -> 0.81649658 | I5: =STDEV('1. Raw Data'!R38:R40,'1. Raw Data'!R42:R43) -> 0.89442719 | J5: Java | K5: =((G5/C5)*100) -> 30.983867 | L5: =((H5/D5)*100) -> 61.237244 | M5: =((I5/E5)*100) -> 63.887656 | N5: Java
A6: 500 | B6: P95 (ms) | C6: =AVERAGE('1. Raw Data'!O8:O12) -> 36.2 | D6: =AVERAGE('1. Raw Data'!O26:O27,'1. Raw Data'!O29:O31) -> 103 | E6: =AVERAGE('1. Raw Data'!O45:O49) -> 216.2 | F6: Java | G6: =STDEV('1. Raw Data'!O8:O12) -> 42.428764 | H6: =STDEV('1. Raw Data'!O26:O27,'1. Raw Data'!O29:O31) -> 128.36861 | I6: =STDEV('1. Raw Data'!O45:O49) -> 280.39294 | J6: Java | K6: =((G6/C6)*100) -> 117.20653 | L6: =((H6/D6)*100) -> 124.62972 | M6: =((I6/E6)*100) -> 129.69146 | N6: Java
B7: P99 (ms) | C7: =AVERAGE('1. Raw Data'!P8:P12) -> 2145.6 | D7: =AVERAGE('1. Raw Data'!P26:P27,'1. Raw Data'!P29:P31) -> 2049 | E7: =AVERAGE('1. Raw Data'!P45:P49) -> 2097 | F7: Idiomatic | G7: =STDEV('1. Raw Data'!P8:P12) -> 838.9823 | H7: =STDEV('1. Raw Data'!P26:P27,'1. Raw Data'!P29:P31) -> 826.28234 | I7: =STDEV('1. Raw Data'!P45:P49) -> 561.92081 | J7: Interop | K7: =((G7/C7)*100) -> 39.102456 | L7: =((H7/D7)*100) -> 40.326127 | M7: =((I7/E7)*100) -> 26.796415 | N7: Interop
B8: GC Time (ms) | C8: =AVERAGE('1. Raw Data'!Q8:Q12) -> 167 | D8: =AVERAGE('1. Raw Data'!Q26:Q27,'1. Raw Data'!Q29:Q31) -> 126.4 | E8: =AVERAGE('1. Raw Data'!Q45:Q49) -> 257.6 | F8: Idiomatic | G8: =STDEV('1. Raw Data'!Q8:Q12) -> 107.0584 | H8: =STDEV('1. Raw Data'!Q26:Q27,'1. Raw Data'!Q29:Q31) -> 21.720958 | I8: =STDEV('1. Raw Data'!Q45:Q49) -> 166.17701 | J8: Idiomatic | K8: =((G8/C8)*100) -> 64.106824 | L8: =((H8/D8)*100) -> 17.184302 | M8: =((I8/E8)*100) -> 64.50971 | N8: idiomatic
B9: GC Collections | C9: =AVERAGE('1. Raw Data'!R8:R12) -> 5.6 | D9: =AVERAGE('1. Raw Data'!R26:R27,'1. Raw Data'!R29:R31) -> 6.4 | E9: =AVERAGE('1. Raw Data'!R45:R49) -> 5.8 | F9: Java | G9: =STDEV('1. Raw Data'!R8:R12) -> 0.89442719 | H9: =STDEV('1. Raw Data'!R26:R27,'1. Raw Data'!R29:R31) -> 0.54772256 | I9: =STDEV('1. Raw Data'!R45:R49) -> 0.4472136 | J9: Interop | K9: =((G9/C9)*100) -> 15.971914 | L9: =((H9/D9)*100) -> 8.558165 | M9: =((I9/E9)*100) -> 7.7105792 | N9: Interop
A10: 1000 | B10: P95 (ms) | C10: =AVERAGE('1. Raw Data'!O14:O18) -> 5863 | D10: =AVERAGE('1. Raw Data'!O32,'1. Raw Data'!O34:O36) -> 9612.25 | E10: =AVERAGE('1. Raw Data'!O51:O55) -> 5712.6 | F10: Interop | G10: =STDEV('1. Raw Data'!O14:O18) -> 1368.5121 | H10: =STDEV('1. Raw Data'!O32,'1. Raw Data'!O34:O36) -> 5298.8618 | I10: =STDEV('1. Raw Data'!O51:O55) -> 1050.7644 | J10: Interop | K10: =(G10/C10)*100 -> 23.3415 | L10: =(H10/D10)*100 -> 55.126134 | M10: =(I10/E10)*100 -> 18.393803 | N10: interop
B11: P99 (ms) | C11: =AVERAGE('1. Raw Data'!P14:P18) -> 10710.6 | D11: =AVERAGE('1. Raw Data'!P32,'1. Raw Data'!P34:P36) -> 14015.5 | E11: =AVERAGE('1. Raw Data'!P51:P55) -> 11865.8 | F11: Java | G11: =STDEV('1. Raw Data'!P14:P18) -> 1598.8802 | H11: =STDEV('1. Raw Data'!P32,'1. Raw Data'!P34:P36) -> 6033.253 | I11: =STDEV('1. Raw Data'!P51:P55) -> 2395.8347 | J11: Interop | K11: =(G11/C11)*100 -> 14.928017 | L11: =(H11/D11)*100 -> 43.047005 | M11: =(I11/E11)*100 -> 20.191093 | N11: Java
B12: GC Time (ms) | C12: =AVERAGE('1. Raw Data'!Q14:Q18) -> 1191 | D12: =AVERAGE('1. Raw Data'!Q32,'1. Raw Data'!Q34:Q36) -> 1539 | E12: =AVERAGE('1. Raw Data'!Q51:Q55) -> 1015 | F12: Interop | G12: =STDEV('1. Raw Data'!Q14:Q18) -> 366.05874 | H12: =STDEV('1. Raw Data'!Q32,'1. Raw Data'!Q34:Q36) -> 484.20175 | I12: =STDEV('1. Raw Data'!Q51:Q55) -> 398.57371 | J12: Java | K12: =(G12/C12)*100 -> 30.73541 | L12: =(H12/D12)*100 -> 31.462102 | M12: =(I12/E12)*100 -> 39.268346 | N12: Java
B13: GC Collections | C13: =AVERAGE('1. Raw Data'!R14:R18) -> 13.6 | D13: =AVERAGE('1. Raw Data'!R32,'1. Raw Data'!R34:R36) -> 17.75 | E13: =AVERAGE('1. Raw Data'!R51:R55) -> 12.4 | F13: Interop | G13: =STDEV('1. Raw Data'!R14:R18) -> 2.3021729 | H13: =STDEV('1. Raw Data'!R32,'1. Raw Data'!R34:R36) -> 2.3629078 | I13: =STDEV('1. Raw Data'!R51:R55) -> 1.1401754 | J13: Interop | K13: =(G13/C13)*100 -> 16.927742 | L13: =(H13/D13)*100 -> 13.312157 | M13: =(I13/E13)*100 -> 9.1949631 | N13: Interop

Sheet 5. Performance Analysis
A1: Load | B1: Metric | C1: Java AVG (tab 3) | D1: Idiomatic AVG (tab 3) | E1: Interop AVG (tab 3) | F1: Best | G1: Δ | H1: Dimension
A2: 100 | B2: P95 (ms) | C2: =AVERAGE('1. Raw Data'!O2:O7) -> 2.3333333 | D2: =AVERAGE('1. Raw Data'!O20:O25) -> 2 | E2: =AVERAGE('1. Raw Data'!O38:O40,'1. Raw Data'!O42:O43) -> 2 | F2: DRAW | G2: 0 | H2: P95 Latency
B3: P99 (ms) | C3: =AVERAGE('1. Raw Data'!P2:P7) -> 3.8333333 | D3: =AVERAGE('1. Raw Data'!P20:P25) -> 4 | E3: =AVERAGE('1. Raw Data'!P38:P40,'1. Raw Data'!P42:P43) -> 3.8 | F3: Interop | G3: =(D3-E3)/E3 -> 0.052631579 | H3: P99 Latency
B4: GC Time (ms) | C4: =AVERAGE('1. Raw Data'!Q2:Q7) -> 27.5 | D4: =AVERAGE('1. Raw Data'!Q20:Q25) -> 20.666667 | E4: =AVERAGE('1. Raw Data'!Q38:Q40,'1. Raw Data'!Q42:Q43) -> 22.6 | F4: Idiomatic | G4: =(C4-D4)/D4 -> 0.33064516 | H4: GC Overhead
B5: GC Collections | C5: =AVERAGE('1. Raw Data'!R2:R7) -> 1.6666667 | D5: =AVERAGE('1. Raw Data'!R20:R25) -> 1.3333333 | E5: =AVERAGE('1. Raw Data'!R38:R40,'1. Raw Data'!R42:R43) -> 1.4 | F5: Idiomatic | G5: =(C5-D5)/D5 -> 0.25 | H5: GC Overhead
A6: 500 | B6: P95 (ms) | C6: =AVERAGE('1. Raw Data'!O8:O12) -> 36.2 | D6: =AVERAGE('1. Raw Data'!O26:O27,'1. Raw Data'!O29:O31) -> 103 | E6: =AVERAGE('1. Raw Data'!O45:O49) -> 216.2 | F6: Java | G6: =(E6-C6)/C6 -> 4.9723757 | H6: P95 Latency
B7: P99 (ms) | C7: =AVERAGE('1. Raw Data'!P8:P12) -> 2145.6 | D7: =AVERAGE('1. Raw Data'!P26:P27,'1. Raw Data'!P29:P31) -> 2049 | E7: =AVERAGE('1. Raw Data'!P45:P49) -> 2097 | F7: Idiomatic | G7: =(C7-D7)/D7 -> 0.047144949 | H7: P99 Latency
B8: GC Time (ms) | C8: =AVERAGE('1. Raw Data'!Q8:Q12) -> 167 | D8: =AVERAGE('1. Raw Data'!Q26:Q27,'1. Raw Data'!Q29:Q31) -> 126.4 | E8: =AVERAGE('1. Raw Data'!Q45:Q49) -> 257.6 | F8: Idiomatic | G8: =(E8-D8)/D8 -> 1.0379747 | H8: GC Overhead
B9: GC Collections | C9: =AVERAGE('1. Raw Data'!R8:R12) -> 5.6 | D9: =AVERAGE('1. Raw Data'!R26:R27,'1. Raw Data'!R29:R31) -> 6.4 | E9: =AVERAGE('1. Raw Data'!R45:R49) -> 5.8 | F9: java | G9: =(D9-C9)/C9 -> 0.14285714 | H9: GC Overhead
A10: 1000 | B10: P95 (ms) | C10: =AVERAGE('1. Raw Data'!O14:O18) -> 5863 | D10: =AVERAGE('1. Raw Data'!O32,'1. Raw Data'!O34:O36) -> 9612.25 | E10: =AVERAGE('1. Raw Data'!O51:O55) -> 5712.6 | F10: Interop | G10: =(D10-E10)/E10 -> 0.68264013 | H10: P95 Latency
B11: P99 (ms) | C11: =AVERAGE('1. Raw Data'!P14:P18) -> 10710.6 | D11: =AVERAGE('1. Raw Data'!P32,'1. Raw Data'!P34:P36) -> 14015.5 | E11: =AVERAGE('1. Raw Data'!P51:P55) -> 11865.8 | F11: java | G11: =(D11-C11)/C11 -> 0.30856348 | H11: P99 Latency
B12: GC Time (ms) | C12: =AVERAGE('1. Raw Data'!Q14:Q18) -> 1191 | D12: =AVERAGE('1. Raw Data'!Q32,'1. Raw Data'!Q34:Q36) -> 1539 | E12: =AVERAGE('1. Raw Data'!Q51:Q55) -> 1015 | F12: Interop | G12: =(D12-E12)/E12 -> 0.51625616 | H12: GC Overhead
B13: GC Collections | C13: =AVERAGE('1. Raw Data'!R14:R18) -> 13.6 | D13: =AVERAGE('1. Raw Data'!R32,'1. Raw Data'!R34:R36) -> 17.75 | E13: =AVERAGE('1. Raw Data'!R51:R55) -> 12.4 | F13: Interop | G13: =(D13-E13)/E13 -> 0.43145161 | H13: GC Overhead
